<?xml version="1.0" ?>
<!-- =================================================================================== -->
<!-- |    This document was autogenerated by xacro from 3dof_planar.urdf.xacro         | -->
<!-- |    EDITING THIS FILE BY HAND IS NOT RECOMMENDED                                 | -->
<!-- =================================================================================== -->
<robot name="3dof_planar" xmlns:xacro="http://www.ros.org/wiki/xacro">
  <link name="world"/>
  <joint name="three_dof_planar_joint_world" type="fixed">
    <parent link="world"/>
    <child link="three_dof_planar_link0"/>
    <origin rpy="0 0 0" xyz="0 0 0"/>
  </joint>
  <!-- end for simulation -->
  <link name="three_dof_planar_link0">
    <visual>
      <geometry>
        <box size="0.1 0.1 0.1"/>
      </geometry>
      <origin rpy="0.0 0.0 0.0" xyz="0.0 0.0 0.05"/>
    </visual>
    <collision>
      <geometry>
        <box size="0.1 0.1 0.1"/>
      </geometry>
      <origin rpy="0.0 0.0 0.0" xyz="0.0 0.0 0.05"/>
    </collision>
    <!-- for simulation -->
    <inertial>
      <origin rpy="0 0 0" xyz="0 0 0"/>
      <mass value="5.0"/>
      <inertia ixx="0.0" ixy="0.0" ixz="0.0" iyy="0.0" iyz="0.0" izz="0.0"/>
    </inertial>
    <!-- end for simulation -->
  </link>
  <link name="three_dof_planar_link1">
    <visual>
      <geometry>
        <cylinder length="0.5" radius="0.02"/>
      </geometry>
      <origin rpy="0.0 1.57079632679 0.0" xyz="0.25 0.0 0.0"/>
    </visual>
    <collision>
      <geometry>
        <cylinder length="0.5" radius="0.02"/>
      </geometry>
      <origin rpy="0.0 1.57079632679 0.0" xyz="0.25 0.0 0.0"/>
    </collision>
    <!-- for simulation -->
    <inertial>
      <origin rpy="0 0 0" xyz="0.25 0.0 0.0"/>
      <mass value="1.0"/>
      <!--inertia izz="0.02" ixy="0.0" ixz="0.0" iyy="0.02" iyz="0.0" ixx="0.0002" /-->
      <inertia ixx="0.0" ixy="0.0" ixz="0.0" iyy="0.0" iyz="0.0" izz="0.0"/>
    </inertial>
    <!-- end for simulation -->
  </link>
  <joint name="three_dof_planar_joint1" type="revolute">
    <safety_controller k_position="100.0" k_velocity="40.0" soft_lower_limit="-1.9" soft_upper_limit="1.9"/>
    <origin rpy="0 0 0.785398163397" xyz="0 0 0.05"/>
    <parent link="three_dof_planar_link0"/>
    <child link="three_dof_planar_link1"/>
    <axis xyz="0 0 1"/>
    <limit effort="15" lower="-2" upper="2" velocity="2.1750"/>
    <!-- for simulation -->
    <dynamics damping="0.0" friction="0.546"/>
    <!-- end for simulation -->
  </joint>
  <link name="three_dof_planar_link2">
    <visual>
      <geometry>
        <cylinder length="0.3" radius="0.02"/>
      </geometry>
      <origin rpy="0.0 1.57079632679 0.0" xyz="0.15 0.0 0.0"/>
    </visual>
    <collision>
      <geometry>
        <cylinder length="0.3" radius="0.02"/>
      </geometry>
      <origin rpy="0.0 1.57079632679 0.0" xyz="0.15 0.0 0.0"/>
    </collision>
    <!-- for simulation -->
    <inertial>
      <origin rpy="0 0 0" xyz="0.15 0.0 0.0"/>
      <mass value="0.6"/>
      <!--inertia izz="0.00456" ixy="0.0" ixz="0.0" iyy="0.00456" iyz="0.0" ixx="0.0001" /-->
      <inertia ixx="0.0" ixy="0.0" ixz="0.0" iyy="0.0" iyz="0.0" izz="0.0"/>
    </inertial>
    <!-- end for simulation -->
  </link>
  <joint name="three_dof_planar_joint2" type="revolute">
    <safety_controller k_position="100.0" k_velocity="40.0" soft_lower_limit="-1.9" soft_upper_limit="1.9"/>
    <origin rpy="0 0 -0.392699081699" xyz="0.5 0 0"/>
    <parent link="three_dof_planar_link1"/>
    <child link="three_dof_planar_link2"/>
    <axis xyz="0 0 1"/>
    <limit effort="15" lower="-2" upper="2" velocity="2.1750"/>
    <!-- for simulation -->
    <dynamics damping="0.0" friction="0.546"/>
    <!-- end for simulation -->
  </joint>
  <link name="three_dof_planar_link3">
    <visual>
      <geometry>
        <cylinder length="0.2" radius="0.02"/>
      </geometry>
      <origin rpy="0.0 1.57079632679 0.0" xyz="0.1 0.0 0.0"/>
    </visual>
    <collision>
      <geometry>
        <cylinder length="0.2" radius="0.02"/>
      </geometry>
      <origin rpy="0.0 1.57079632679 0.0" xyz="0.1 0.0 0.0"/>
    </collision>
    <!-- for simulation -->
    <inertial>
      <origin rpy="0 0 0" xyz="0.1 0.0 0.0"/>
      <mass value="0.3"/>
      <!--inertia izz="0.00103" ixy="0.0" ixz="0.0" iyy="0.00103" iyz="0.0" ixx="0.00006" /-->
      <inertia ixx="0.0" ixy="0.0" ixz="0.0" iyy="0.0" iyz="0.0" izz="0.0"/>
    </inertial>
    <!-- end for simulation -->
  </link>
  <joint name="three_dof_planar_joint3" type="revolute">
    <safety_controller k_position="100.0" k_velocity="40.0" soft_lower_limit="-1.9" soft_upper_limit="1.9"/>
    <origin rpy="0 0 -0.392699081699" xyz="0.3 0 0"/>
    <parent link="three_dof_planar_link2"/>
    <child link="three_dof_planar_link3"/>
    <axis xyz="0 0 1"/>
    <limit effort="15" lower="-2" upper="2" velocity="2.1750"/>
    <!-- for simulation -->
    <dynamics damping="0.0" friction="0.546"/>
    <!-- end for simulation -->
  </joint>
  <link name="three_dof_planar_eef">
    <!-- for simulation -->
    <inertial>
      <origin rpy="0 0 0" xyz="0 0 0"/>
      <mass value="0.0"/>
      <inertia ixx="0.0" ixy="0.0" ixz="0.0" iyy="0.0" iyz="0.0" izz="0.0"/>
    </inertial>
    <!-- end for simulation -->
  </link>
  <joint name="three_dof_planar_eef_fixed" type="fixed">
    <origin rpy="0 0 0" xyz="0.2 0 0"/>
    <parent link="three_dof_planar_link3"/>
    <child link="three_dof_planar_eef"/>
    <axis xyz="0 0 0"/>
  </joint>
  <!-- Link0 -->
  <gazebo reference="three_dof_planar_link0">
    <material>Gazebo/Grey</material>
    <mu1>0.2</mu1>
    <mu2>0.2</mu2>
  </gazebo>
  <!-- Link1 -->
  <gazebo reference="three_dof_planar_link1">
    <material>Gazebo/White</material>
    <mu1>0.2</mu1>
    <mu2>0.2</mu2>
  </gazebo>
  <!-- Link2 -->
  <gazebo reference="three_dof_planar_link2">
    <material>Gazebo/White</material>
    <mu1>0.2</mu1>
    <mu2>0.2</mu2>
  </gazebo>
  <!-- Link3 -->
  <gazebo reference="three_dof_planar_link3">
    <material>Gazebo/White</material>
    <mu1>0.2</mu1>
    <mu2>0.2</mu2>
  </gazebo>
  <!-- Link3 -->
  <gazebo reference="three_dof_planar_eef">
    <material>Gazebo/White</material>
    <mu1>0.2</mu1>
    <mu2>0.2</mu2>
  </gazebo>
  <!-- Load Gazebo lib and set the robot namespace -->
  <gazebo>
    <plugin filename="libgazebo_ros_control.so" name="gazebo_ros_control">
      <!--<legacyModeNS>true</legacyModeNS>-->
    </plugin>
  </gazebo>
  <transmission name="three_dof_planar_tran_1">
    <type>transmission_interface/SimpleTransmission</type>
    <joint name="three_dof_planar_joint1">
      <hardwareInterface>hardware_interface/VelocityJointInterface</hardwareInterface>
    </joint>
    <actuator name="three_dof_planar_motor_1">
      <hardwareInterface>hardware_interface/VelocityJointInterface</hardwareInterface>
      <mechanicalReduction>1</mechanicalReduction>
    </actuator>
  </transmission>
  <transmission name="three_dof_planar_tran_2">
    <type>transmission_interface/SimpleTransmission</type>
    <joint name="three_dof_planar_joint2">
      <hardwareInterface>hardware_interface/VelocityJointInterface</hardwareInterface>
    </joint>
    <actuator name="three_dof_planar_motor_2">
      <hardwareInterface>hardware_interface/VelocityJointInterface</hardwareInterface>
      <mechanicalReduction>1</mechanicalReduction>
    </actuator>
  </transmission>
  <transmission name="three_dof_planar_tran_3">
    <type>transmission_interface/SimpleTransmission</type>
    <joint name="three_dof_planar_joint3">
      <hardwareInterface>hardware_interface/VelocityJointInterface</hardwareInterface>
    </joint>
    <actuator name="three_dof_planar_motor_3">
      <hardwareInterface>hardware_interface/VelocityJointInterface</hardwareInterface>
      <mechanicalReduction>1</mechanicalReduction>
    </actuator>
  </transmission>
</robot>

